<sdf version='1.7'>
  <model name='gen3'>
    <link name='dummy'>
      <inertial>
        <pose>-0.00527 0 0 0 -0 0</pose>
        <mass>111</mass>
        <inertia>
          <ixx>3.0863</ixx>
          <ixy>0</ixy>
          <ixz>0</ixz>
          <iyy>16.4359</iyy>
          <iyz>0</iyz>
          <izz>18.6086</izz>
        </inertia>
      </inertial>
      <collision name='dummy_fixed_joint_lump__base_link_collision'>
        <pose>0 0 0.15 0 -0 0</pose>
        <geometry>
          <box>
            <size>1.34 0.42 0.225</size>
          </box>
        </geometry>
      </collision>
      <collision name='dummy_fixed_joint_lump__left_body_collision_1'>
        <pose>0 0.32 0 0 -0 0</pose>
        <geometry>
          <box>
            <size>0.9 0.19 0.2</size>
          </box>
        </geometry>
      </collision>
      <collision name='dummy_fixed_joint_lump__left_idler_collision_2'>
        <pose>-0.585 0.32 0 1.5708 -0 0</pose>
        <geometry>
          <cylinder>
            <length>0.19</length>
            <radius>0.08</radius>
          </cylinder>
        </geometry>
      </collision>
      <collision name='dummy_fixed_joint_lump__right_body_collision_3'>
        <pose>0 -0.32 0 0 -0 0</pose>
        <geometry>
          <box>
            <size>0.9 0.19 0.2</size>
          </box>
        </geometry>
      </collision>
      <collision name='dummy_fixed_joint_lump__right_idler_collision_4'>
        <pose>-0.585 -0.32 0 1.5708 -0 0</pose>
        <geometry>
          <cylinder>
            <length>0.19</length>
            <radius>0.08</radius>
          </cylinder>
        </geometry>
      </collision>
      <visual name='dummy_fixed_joint_lump__base_link_visual'>
        <pose>0 0 0.15 0 -0 0</pose>
        <geometry>
          <box>
            <size>1.34 0.42 0.225</size>
          </box>
        </geometry>
      </visual>
      <visual name='dummy_fixed_joint_lump__imu_link_visual_1'>
        <pose>0 0 0.2 0 -0 0</pose>
        <geometry>
          <box>
            <size>0.02 0.02 0.02</size>
          </box>
        </geometry>
      </visual>
      <visual name='dummy_fixed_joint_lump__left_body_visual_2'>
        <pose>0 0.32 0 0 -0 0</pose>
        <geometry>
          <box>
            <size>0.9 0.19 0.2</size>
          </box>
        </geometry>
      </visual>
      <visual name='dummy_fixed_joint_lump__left_idler_visual_3'>
        <pose>-0.585 0.32 0 1.5708 -0 0</pose>
        <geometry>
          <cylinder>
            <length>0.19</length>
            <radius>0.08</radius>
          </cylinder>
        </geometry>
      </visual>
      <visual name='dummy_fixed_joint_lump__right_body_visual_4'>
        <pose>0 -0.32 0 0 -0 0</pose>
        <geometry>
          <box>
            <size>0.9 0.19 0.2</size>
          </box>
        </geometry>
      </visual>
      <visual name='dummy_fixed_joint_lump__right_idler_visual_5'>
        <pose>-0.585 -0.32 0 1.5708 -0 0</pose>
        <geometry>
          <cylinder>
            <length>0.19</length>
            <radius>0.08</radius>
          </cylinder>
        </geometry>
      </visual>
      <gravity>1</gravity>
      <velocity_decay/>
      <gravity>1</gravity>
      <sensor name='imu_sensor' type='imu'>
        <imu>
          <angular_velocity>
            <x>
              <noise type='gaussian'>
                <mean>0</mean>
                <stddev>0.0002</stddev>
                <bias_mean>7.5e-06</bias_mean>
                <bias_stddev>8e-07</bias_stddev>
              </noise>
            </x>
            <y>
              <noise type='gaussian'>
                <mean>0</mean>
                <stddev>0.0002</stddev>
                <bias_mean>7.5e-06</bias_mean>
                <bias_stddev>8e-07</bias_stddev>
              </noise>
            </y>
            <z>
              <noise type='gaussian'>
                <mean>0</mean>
                <stddev>0.0002</stddev>
                <bias_mean>7.5e-06</bias_mean>
                <bias_stddev>8e-07</bias_stddev>
              </noise>
            </z>
          </angular_velocity>
          <linear_acceleration>
            <x>
              <noise type='gaussian'>
                <mean>0</mean>
                <stddev>0.017</stddev>
                <bias_mean>0.1</bias_mean>
                <bias_stddev>0.001</bias_stddev>
              </noise>
            </x>
            <y>
              <noise type='gaussian'>
                <mean>0</mean>
                <stddev>0.017</stddev>
                <bias_mean>0.1</bias_mean>
                <bias_stddev>0.001</bias_stddev>
              </noise>
            </y>
            <z>
              <noise type='gaussian'>
                <mean>0</mean>
                <stddev>0.017</stddev>
                <bias_mean>0.1</bias_mean>
                <bias_stddev>0.001</bias_stddev>
              </noise>
            </z>
          </linear_acceleration>
        </imu>
        <always_on>1</always_on>
        <update_rate>100</update_rate>
        <visualize>1</visualize>
        <topic>__default_topic__</topic>
        <plugin name='imu_plugin' filename='libgazebo_ros_imu_sensor.so'>
          <topicName>imu</topicName>
          <bodyName>imu_link</bodyName>
          <updateRateHZ>10.0</updateRateHZ>
          <gaussianNoise>0.0</gaussianNoise>
          <xyzOffset>0 0 0</xyzOffset>
          <rpyOffset>0 0 0</rpyOffset>
          <frameName>imu_link</frameName>
          <initialOrientationAsReference>0</initialOrientationAsReference>
        </plugin>
        <pose>0 0 0.2 0 -0 0</pose>
      </sensor>
    </link>
    <joint name='left_sprocket_axle' type='revolute'>
      <pose relative_to='dummy'>0.585 0.32 0 0 -0 0</pose>
      <parent>dummy</parent>
      <child>left_sprocket</child>
      <axis>
        <xyz>0 1 0</xyz>
        <limit>
          <lower>-1e+16</lower>
          <upper>1e+16</upper>
        </limit>
        <dynamics>
          <spring_reference>0</spring_reference>
          <spring_stiffness>0</spring_stiffness>
        </dynamics>
      </axis>
    </joint>
    <link name='left_sprocket'>
      <pose relative_to='left_sprocket_axle'>0 0 0 0 -0 0</pose>
      <inertial>
        <pose>0 0 0 0 -0 0</pose>
        <mass>1</mass>
        <inertia>
          <ixx>0.00460833</ixx>
          <ixy>0</ixy>
          <ixz>0</ixz>
          <iyy>0.0032</iyy>
          <iyz>0</iyz>
          <izz>0.00460833</izz>
        </inertia>
      </inertial>
      <collision name='left_sprocket_collision'>
        <pose>0 0 0 1.5708 -0 0</pose>
        <geometry>
          <cylinder>
            <length>0.19</length>
            <radius>0.08</radius>
          </cylinder>
        </geometry>
      </collision>
      <visual name='left_sprocket_visual'>
        <pose>0 0 0 1.5708 -0 0</pose>
        <geometry>
          <cylinder>
            <length>0.19</length>
            <radius>0.08</radius>
          </cylinder>
        </geometry>
      </visual>
      <visual name='left_sprocket_visual_1'>
        <pose>0 0 0 0 -0 0</pose>
        <geometry>
          <box>
            <size>0.01 0.19 0.2</size>
          </box>
        </geometry>
      </visual>
      <visual name='left_sprocket_visual_2'>
        <pose>0 0 0 0 -0 0</pose>
        <geometry>
          <box>
            <size>0.2 0.19 0.01</size>
          </box>
        </geometry>
      </visual>
    </link>
    <joint name='right_sprocket_axle' type='revolute'>
      <pose relative_to='dummy'>0.585 -0.32 0 0 -0 0</pose>
      <parent>dummy</parent>
      <child>right_sprocket</child>
      <axis>
        <xyz>0 1 0</xyz>
        <limit>
          <lower>-1e+16</lower>
          <upper>1e+16</upper>
        </limit>
        <dynamics>
          <spring_reference>0</spring_reference>
          <spring_stiffness>0</spring_stiffness>
        </dynamics>
      </axis>
    </joint>
    <link name='right_sprocket'>
      <pose relative_to='right_sprocket_axle'>0 0 0 0 -0 0</pose>
      <inertial>
        <pose>0 0 0 0 -0 0</pose>
        <mass>1</mass>
        <inertia>
          <ixx>0.00460833</ixx>
          <ixy>0</ixy>
          <ixz>0</ixz>
          <iyy>0.0032</iyy>
          <iyz>0</iyz>
          <izz>0.00460833</izz>
        </inertia>
      </inertial>
      <collision name='right_sprocket_collision'>
        <pose>0 0 0 1.5708 -0 0</pose>
        <geometry>
          <cylinder>
            <length>0.19</length>
            <radius>0.08</radius>
          </cylinder>
        </geometry>
      </collision>
      <visual name='right_sprocket_visual'>
        <pose>0 0 0 1.5708 -0 0</pose>
        <geometry>
          <cylinder>
            <length>0.19</length>
            <radius>0.08</radius>
          </cylinder>
        </geometry>
      </visual>
      <visual name='right_sprocket_visual_1'>
        <pose>0 0 0 0 -0 0</pose>
        <geometry>
          <box>
            <size>0.01 0.19 0.2</size>
          </box>
        </geometry>
      </visual>
      <visual name='right_sprocket_visual_2'>
        <pose>0 0 0 0 -0 0</pose>
        <geometry>
          <box>
            <size>0.2 0.19 0.01</size>
          </box>
        </geometry>
      </visual>
    </link>
    <link name='right_track_straight_segment_link0'>
      <pose>-0.6 -0.32 0.12 0 -0 0</pose>
      <inertial>
        <pose>0.6 0 -0.06 0 -0 0</pose>
        <mass>6.75</mass>
        <inertia>
          <ixx>0.026325</ixx>
          <ixy>0</ixy>
          <ixz>0</ixz>
          <iyy>0.8181</iyy>
          <iyz>0</iyz>
          <izz>0.828225</izz>
        </inertia>
      </inertial>
      <collision name='collision'>
        <pose>0.6 0 -0.06 0 -0 0</pose>
        <geometry>
          <box>
            <size>1.2 0.18 0.12</size>
          </box>
        </geometry>
        <surface>
          <friction>
            <ode>
              <mu>10</mu>
              <mu2>10</mu2>
            </ode>
          </friction>
          <contact>
            <ode>
              <min_depth>0.01</min_depth>
            </ode>
          </contact>
        </surface>
      </collision>
      <visual name='visual'>
        <pose>0.6 0 -0.06 0 -0 0</pose>
        <geometry>
          <box>
            <size>1.2 0.18 0.12</size>
          </box>
        </geometry>
        <material>
          <ambient>0.1 0.1 0.1 1</ambient>
          <diffuse>0.2 0.2 0.2 1</diffuse>
          <specular>0 0 0 1</specular>
          <emissive>0 0 0 1</emissive>
        </material>
      </visual>
    </link>
    <link name='right_track_straight_segment_link1'>
      <pose>0.6 -0.32 -0.12 3.14159 0 3.14159</pose>
      <inertial>
        <pose>0.6 0 -0.06 0 -0 0</pose>
        <mass>6.75</mass>
        <inertia>
          <ixx>0.026325</ixx>
          <ixy>0</ixy>
          <ixz>0</ixz>
          <iyy>0.8181</iyy>
          <iyz>0</iyz>
          <izz>0.828225</izz>
        </inertia>
      </inertial>
      <collision name='collision'>
        <pose>0.6 0 -0.06 0 -0 0</pose>
        <geometry>
          <box>
            <size>1.2 0.18 0.12</size>
          </box>
        </geometry>
        <surface>
          <friction>
            <ode>
              <mu>10</mu>
              <mu2>10</mu2>
            </ode>
          </friction>
          <contact>
            <ode>
              <min_depth>0.01</min_depth>
            </ode>
          </contact>
        </surface>
      </collision>
      <visual name='visual'>
        <pose>0.6 0 -0.06 0 -0 0</pose>
        <geometry>
          <box>
            <size>1.2 0.18 0.12</size>
          </box>
        </geometry>
        <material>
          <ambient>0.1 0.1 0.1 1</ambient>
          <diffuse>0.2 0.2 0.2 1</diffuse>
          <specular>0 0 0 1</specular>
          <emissive>0 0 0 1</emissive>
        </material>
      </visual>
    </link>
    <joint name='right_track_straight_segment_joint0' type='prismatic'>
      <child>right_track_straight_segment_link0</child>
      <axis>
        <xyz>1 0 0</xyz>
        <use_parent_model_frame>0</use_parent_model_frame>
        <limit>
          <lower>-1e+16</lower>
          <upper>1e+16</upper>
        </limit>
      </axis>
      <physics>
        <ode>
          <implicit_spring_damper>1</implicit_spring_damper>
        </ode>
      </physics>
      <parent>dummy</parent>
    </joint>
    <joint name='right_track_straight_segment_joint1' type='prismatic'>
      <child>right_track_straight_segment_link1</child>
      <axis>
        <xyz>1 0 0</xyz>
        <use_parent_model_frame>0</use_parent_model_frame>
        <limit>
          <lower>-1e+16</lower>
          <upper>1e+16</upper>
        </limit>
      </axis>
      <physics>
        <ode>
          <implicit_spring_damper>1</implicit_spring_damper>
        </ode>
      </physics>
      <parent>dummy</parent>
    </joint>
    <link name='right_track_arc_segment_link0'>
      <pose>0.6 -0.32 0.12 0 -0 0</pose>
      <inertial>
        <pose>0 0 -0.12 1.5708 -0 0</pose>
        <mass>6.75</mass>
        <inertia>
          <ixx>0.042525</ixx>
          <ixy>0</ixy>
          <ixz>0</ixz>
          <iyy>0.042525</iyy>
          <iyz>0</iyz>
          <izz>0.0486</izz>
        </inertia>
      </inertial>
      <collision name='collision'>
        <pose>0 0 -0.12 1.5708 -0 0</pose>
        <geometry>
          <cylinder>
            <length>0.18</length>
            <radius>0.12</radius>
          </cylinder>
        </geometry>
        <surface>
          <friction>
            <ode>
              <mu>10</mu>
              <mu2>10</mu2>
            </ode>
          </friction>
          <contact>
            <ode>
              <min_depth>0.01</min_depth>
            </ode>
          </contact>
        </surface>
      </collision>
      <visual name='visual'>
        <pose>0 0 -0.12 1.5708 -0 0</pose>
        <geometry>
          <cylinder>
            <length>0.18</length>
            <radius>0.12</radius>
          </cylinder>
        </geometry>
        <material>
          <ambient>0.1 0.1 0.1 1</ambient>
          <diffuse>0.2 0.2 0.2 1</diffuse>
          <specular>0 0 0 1</specular>
          <emissive>0 0 0 1</emissive>
        </material>
      </visual>
    </link>
    <link name='right_track_arc_segment_link1'>
      <pose>-0.6 -0.32 -0.12 3.14159 0 3.14159</pose>
      <inertial>
        <pose>0 0 -0.12 1.5708 -0 0</pose>
        <mass>6.75</mass>
        <inertia>
          <ixx>0.042525</ixx>
          <ixy>0</ixy>
          <ixz>0</ixz>
          <iyy>0.042525</iyy>
          <iyz>0</iyz>
          <izz>0.0486</izz>
        </inertia>
      </inertial>
      <collision name='collision'>
        <pose>0 0 -0.12 1.5708 -0 0</pose>
        <geometry>
          <cylinder>
            <length>0.18</length>
            <radius>0.12</radius>
          </cylinder>
        </geometry>
        <surface>
          <friction>
            <ode>
              <mu>10</mu>
              <mu2>10</mu2>
            </ode>
          </friction>
          <contact>
            <ode>
              <min_depth>0.01</min_depth>
            </ode>
          </contact>
        </surface>
      </collision>
      <visual name='visual'>
        <pose>0 0 -0.12 1.5708 -0 0</pose>
        <geometry>
          <cylinder>
            <length>0.18</length>
            <radius>0.12</radius>
          </cylinder>
        </geometry>
        <material>
          <ambient>0.1 0.1 0.1 1</ambient>
          <diffuse>0.2 0.2 0.2 1</diffuse>
          <specular>0 0 0 1</specular>
          <emissive>0 0 0 1</emissive>
        </material>
      </visual>
    </link>
    <joint name='right_track_arc_segment_joint0' type='revolute'>
      <child>right_track_arc_segment_link0</child>
      <pose>0 0 -0.12 0 -0 0</pose>
      <axis>
        <xyz>0 1 0</xyz>
        <use_parent_model_frame>0</use_parent_model_frame>
        <limit>
          <lower>-1e+16</lower>
          <upper>1e+16</upper>
        </limit>
      </axis>
      <physics>
        <ode>
          <implicit_spring_damper>1</implicit_spring_damper>
        </ode>
      </physics>
      <parent>dummy</parent>
    </joint>
    <joint name='right_track_arc_segment_joint1' type='revolute'>
      <child>right_track_arc_segment_link1</child>
      <pose>0 0 -0.12 0 -0 0</pose>
      <axis>
        <xyz>0 1 0</xyz>
        <use_parent_model_frame>0</use_parent_model_frame>
        <limit>
          <lower>-1e+16</lower>
          <upper>1e+16</upper>
        </limit>
      </axis>
      <physics>
        <ode>
          <implicit_spring_damper>1</implicit_spring_damper>
        </ode>
      </physics>
      <parent>dummy</parent>
    </joint>
    <plugin name='right_track' filename='libContinuousTrack.so'>
      <sprocket>
        <joint>right_sprocket_axle</joint>
        <pitch_diameter>0.22</pitch_diameter>
      </sprocket>
      <trajectory>
        <segment>
          <joint>right_track_straight_segment_joint0</joint>
          <end_position>1.2</end_position>
        </segment>
        <segment>
          <joint>right_track_arc_segment_joint0</joint>
          <end_position>3.141592653589793</end_position>
        </segment>
        <segment>
          <joint>right_track_straight_segment_joint1</joint>
          <end_position>1.2</end_position>
        </segment>
        <segment>
          <joint>right_track_arc_segment_joint1</joint>
          <end_position>3.141592653589793</end_position>
        </segment>
      </trajectory>
      <pattern>
        <elements_per_round>40</elements_per_round>
        <element>
          <collision name='collision'>
            <pose>0 0.09 0 1.5707963267948966 0 0</pose>
            <geometry>
              <polyline>
                <point>-0.02 -0.01</point>
                <point>-0.01 0.01</point>
                <point>0.01 0.01</point>
                <point>0.02 -0.01</point>
                <height>0.18</height>
              </polyline>
            </geometry>
            <surface>
              <friction>
                <ode>
                  <mu>10</mu>
                  <mu2>10</mu2>
                </ode>
              </friction>
              <contact>
                <ode>
                  <min_depth>0.01</min_depth>
                </ode>
              </contact>
            </surface>
          </collision>
          <visual name='visual'>
            <pose>0 0.09 0 1.5707963267948966 0 0</pose>
            <geometry>
              <polyline>
                <point>-0.02 -0.01</point>
                <point>-0.01 0.01</point>
                <point>0.01 0.01</point>
                <point>0.02 -0.01</point>
                <height>0.18</height>
              </polyline>
            </geometry>
            <material>
              <ambient>0.1 0.1 0.1 1</ambient>
              <diffuse>0.2 0.2 0.2 1</diffuse>
              <specular>0 0 0 1</specular>
              <emissive>0 0 0 1</emissive>
            </material>
          </visual>
        </element>
      </pattern>
    </plugin>
    <link name='left_track_straight_segment_link0'>
      <pose>-0.6 0.32 0.12 0 -0 0</pose>
      <inertial>
        <pose>0.6 0 -0.06 0 -0 0</pose>
        <mass>6.75</mass>
        <inertia>
          <ixx>0.026325</ixx>
          <ixy>0</ixy>
          <ixz>0</ixz>
          <iyy>0.8181</iyy>
          <iyz>0</iyz>
          <izz>0.828225</izz>
        </inertia>
      </inertial>
      <collision name='collision'>
        <pose>0.6 0 -0.06 0 -0 0</pose>
        <geometry>
          <box>
            <size>1.2 0.18 0.12</size>
          </box>
        </geometry>
        <surface>
          <friction>
            <ode>
              <mu>10</mu>
              <mu2>10</mu2>
            </ode>
          </friction>
          <contact>
            <ode>
              <min_depth>0.01</min_depth>
            </ode>
          </contact>
        </surface>
      </collision>
      <visual name='visual'>
        <pose>0.6 0 -0.06 0 -0 0</pose>
        <geometry>
          <box>
            <size>1.2 0.18 0.12</size>
          </box>
        </geometry>
        <material>
          <ambient>0.1 0.1 0.1 1</ambient>
          <diffuse>0.2 0.2 0.2 1</diffuse>
          <specular>0 0 0 1</specular>
          <emissive>0 0 0 1</emissive>
        </material>
      </visual>
    </link>
    <link name='left_track_straight_segment_link1'>
      <pose>0.6 0.32 -0.12 3.14159 0 3.14159</pose>
      <inertial>
        <pose>0.6 0 -0.06 0 -0 0</pose>
        <mass>6.75</mass>
        <inertia>
          <ixx>0.026325</ixx>
          <ixy>0</ixy>
          <ixz>0</ixz>
          <iyy>0.8181</iyy>
          <iyz>0</iyz>
          <izz>0.828225</izz>
        </inertia>
      </inertial>
      <collision name='collision'>
        <pose>0.6 0 -0.06 0 -0 0</pose>
        <geometry>
          <box>
            <size>1.2 0.18 0.12</size>
          </box>
        </geometry>
        <surface>
          <friction>
            <ode>
              <mu>10</mu>
              <mu2>10</mu2>
            </ode>
          </friction>
          <contact>
            <ode>
              <min_depth>0.01</min_depth>
            </ode>
          </contact>
        </surface>
      </collision>
      <visual name='visual'>
        <pose>0.6 0 -0.06 0 -0 0</pose>
        <geometry>
          <box>
            <size>1.2 0.18 0.12</size>
          </box>
        </geometry>
        <material>
          <ambient>0.1 0.1 0.1 1</ambient>
          <diffuse>0.2 0.2 0.2 1</diffuse>
          <specular>0 0 0 1</specular>
          <emissive>0 0 0 1</emissive>
        </material>
      </visual>
    </link>
    <joint name='left_track_straight_segment_joint0' type='prismatic'>
      <child>left_track_straight_segment_link0</child>
      <axis>
        <xyz>1 0 0</xyz>
        <use_parent_model_frame>0</use_parent_model_frame>
        <limit>
          <lower>-1e+16</lower>
          <upper>1e+16</upper>
        </limit>
      </axis>
      <physics>
        <ode>
          <implicit_spring_damper>1</implicit_spring_damper>
        </ode>
      </physics>
      <parent>dummy</parent>
    </joint>
    <joint name='left_track_straight_segment_joint1' type='prismatic'>
      <child>left_track_straight_segment_link1</child>
      <axis>
        <xyz>1 0 0</xyz>
        <use_parent_model_frame>0</use_parent_model_frame>
        <limit>
          <lower>-1e+16</lower>
          <upper>1e+16</upper>
        </limit>
      </axis>
      <physics>
        <ode>
          <implicit_spring_damper>1</implicit_spring_damper>
        </ode>
      </physics>
      <parent>dummy</parent>
    </joint>
    <link name='left_track_arc_segment_link0'>
      <pose>0.6 0.32 0.12 0 -0 0</pose>
      <inertial>
        <pose>0 0 -0.12 1.5708 -0 0</pose>
        <mass>6.75</mass>
        <inertia>
          <ixx>0.042525</ixx>
          <ixy>0</ixy>
          <ixz>0</ixz>
          <iyy>0.042525</iyy>
          <iyz>0</iyz>
          <izz>0.0486</izz>
        </inertia>
      </inertial>
      <collision name='collision'>
        <pose>0 0 -0.12 1.5708 -0 0</pose>
        <geometry>
          <cylinder>
            <length>0.18</length>
            <radius>0.12</radius>
          </cylinder>
        </geometry>
        <surface>
          <friction>
            <ode>
              <mu>10</mu>
              <mu2>10</mu2>
            </ode>
          </friction>
          <contact>
            <ode>
              <min_depth>0.01</min_depth>
            </ode>
          </contact>
        </surface>
      </collision>
      <visual name='visual'>
        <pose>0 0 -0.12 1.5708 -0 0</pose>
        <geometry>
          <cylinder>
            <length>0.18</length>
            <radius>0.12</radius>
          </cylinder>
        </geometry>
        <material>
          <ambient>0.1 0.1 0.1 1</ambient>
          <diffuse>0.2 0.2 0.2 1</diffuse>
          <specular>0 0 0 1</specular>
          <emissive>0 0 0 1</emissive>
        </material>
      </visual>
    </link>
    <link name='left_track_arc_segment_link1'>
      <pose>-0.6 0.32 -0.12 3.14159 0 3.14159</pose>
      <inertial>
        <pose>0 0 -0.12 1.5708 -0 0</pose>
        <mass>6.75</mass>
        <inertia>
          <ixx>0.042525</ixx>
          <ixy>0</ixy>
          <ixz>0</ixz>
          <iyy>0.042525</iyy>
          <iyz>0</iyz>
          <izz>0.0486</izz>
        </inertia>
      </inertial>
      <collision name='collision'>
        <pose>0 0 -0.12 1.5708 -0 0</pose>
        <geometry>
          <cylinder>
            <length>0.18</length>
            <radius>0.12</radius>
          </cylinder>
        </geometry>
        <surface>
          <friction>
            <ode>
              <mu>10</mu>
              <mu2>10</mu2>
            </ode>
          </friction>
          <contact>
            <ode>
              <min_depth>0.01</min_depth>
            </ode>
          </contact>
        </surface>
      </collision>
      <visual name='visual'>
        <pose>0 0 -0.12 1.5708 -0 0</pose>
        <geometry>
          <cylinder>
            <length>0.18</length>
            <radius>0.12</radius>
          </cylinder>
        </geometry>
        <material>
          <ambient>0.1 0.1 0.1 1</ambient>
          <diffuse>0.2 0.2 0.2 1</diffuse>
          <specular>0 0 0 1</specular>
          <emissive>0 0 0 1</emissive>
        </material>
      </visual>
    </link>
    <joint name='left_track_arc_segment_joint0' type='revolute'>
      <child>left_track_arc_segment_link0</child>
      <pose>0 0 -0.12 0 -0 0</pose>
      <axis>
        <xyz>0 1 0</xyz>
        <use_parent_model_frame>0</use_parent_model_frame>
        <limit>
          <lower>-1e+16</lower>
          <upper>1e+16</upper>
        </limit>
      </axis>
      <physics>
        <ode>
          <implicit_spring_damper>1</implicit_spring_damper>
        </ode>
      </physics>
      <parent>dummy</parent>
    </joint>
    <joint name='left_track_arc_segment_joint1' type='revolute'>
      <child>left_track_arc_segment_link1</child>
      <pose>0 0 -0.12 0 -0 0</pose>
      <axis>
        <xyz>0 1 0</xyz>
        <use_parent_model_frame>0</use_parent_model_frame>
        <limit>
          <lower>-1e+16</lower>
          <upper>1e+16</upper>
        </limit>
      </axis>
      <physics>
        <ode>
          <implicit_spring_damper>1</implicit_spring_damper>
        </ode>
      </physics>
      <parent>dummy</parent>
    </joint>
    <plugin name='left_track' filename='libContinuousTrack.so'>
      <sprocket>
        <joint>left_sprocket_axle</joint>
        <pitch_diameter>0.22</pitch_diameter>
      </sprocket>
      <trajectory>
        <segment>
          <joint>left_track_straight_segment_joint0</joint>
          <end_position>1.2</end_position>
        </segment>
        <segment>
          <joint>left_track_arc_segment_joint0</joint>
          <end_position>3.141592653589793</end_position>
        </segment>
        <segment>
          <joint>left_track_straight_segment_joint1</joint>
          <end_position>1.2</end_position>
        </segment>
        <segment>
          <joint>left_track_arc_segment_joint1</joint>
          <end_position>3.141592653589793</end_position>
        </segment>
      </trajectory>
      <pattern>
        <elements_per_round>40</elements_per_round>
        <element>
          <collision name='collision'>
            <pose>0 0.09 0 1.5707963267948966 0 0</pose>
            <geometry>
              <polyline>
                <point>-0.02 -0.01</point>
                <point>-0.01 0.01</point>
                <point>0.01 0.01</point>
                <point>0.02 -0.01</point>
                <height>0.18</height>
              </polyline>
            </geometry>
            <surface>
              <friction>
                <ode>
                  <mu>10</mu>
                  <mu2>10</mu2>
                </ode>
              </friction>
              <contact>
                <ode>
                  <min_depth>0.01</min_depth>
                </ode>
              </contact>
            </surface>
          </collision>
          <visual name='visual'>
            <pose>0 0.09 0 1.5707963267948966 0 0</pose>
            <geometry>
              <polyline>
                <point>-0.02 -0.01</point>
                <point>-0.01 0.01</point>
                <point>0.01 0.01</point>
                <point>0.02 -0.01</point>
                <height>0.18</height>
              </polyline>
            </geometry>
            <material>
              <ambient>0.1 0.1 0.1 1</ambient>
              <diffuse>0.2 0.2 0.2 1</diffuse>
              <specular>0 0 0 1</specular>
              <emissive>0 0 0 1</emissive>
            </material>
          </visual>
        </element>
      </pattern>
    </plugin>
    <static>0</static>
    <plugin name='gazebo_ros_control' filename='libgazebo_ros_control.so'>
      <robotNamespace>/</robotNamespace>
      <legacyModeNS>1</legacyModeNS>
    </plugin>
  </model>
</sdf>
